2021-09-21 20:45:52,273 INFO: Myblog startup [in C:\Users\Admin\PycharmProjects\fDemo\app\__init__.py:45]
2021-09-23 19:11:19,144 INFO: Myblog startup [in C:\Users\Admin\PycharmProjects\fDemo\app\__init__.py:44]
2021-09-24 11:41:20,549 INFO: Myblog startup [in C:\Users\Admin\PycharmProjects\fDemo\app\__init__.py:44]
2021-09-24 11:49:13,346 ERROR: Exception on /edit_profile [POST] [in c:\users\admin\pycharmprojects\fdemo\venv\lib\site-packages\flask\app.py:1454]
Traceback (most recent call last):
  File "c:\users\admin\pycharmprojects\fdemo\venv\lib\site-packages\sqlalchemy\engine\base.py", line 1771, in _execute_context
    self.dialect.do_execute(
  File "c:\users\admin\pycharmprojects\fdemo\venv\lib\site-packages\sqlalchemy\engine\default.py", line 717, in do_execute
    cursor.execute(statement, parameters)
sqlite3.IntegrityError: UNIQUE constraint failed: user.username

The above exception was the direct cause of the following exception:

Traceback (most recent call last):
  File "c:\users\admin\pycharmprojects\fdemo\venv\lib\site-packages\flask\app.py", line 2070, in wsgi_app
    response = self.full_dispatch_request()
  File "c:\users\admin\pycharmprojects\fdemo\venv\lib\site-packages\flask\app.py", line 1515, in full_dispatch_request
    rv = self.handle_user_exception(e)
  File "c:\users\admin\pycharmprojects\fdemo\venv\lib\site-packages\flask\app.py", line 1513, in full_dispatch_request
    rv = self.dispatch_request()
  File "c:\users\admin\pycharmprojects\fdemo\venv\lib\site-packages\flask\app.py", line 1499, in dispatch_request
    return self.ensure_sync(self.view_functions[rule.endpoint])(**req.view_args)
  File "c:\users\admin\pycharmprojects\fdemo\venv\lib\site-packages\flask_login\utils.py", line 272, in decorated_view
    return func(*args, **kwargs)
  File "C:\Users\Admin\PycharmProjects\fDemo\app\routes.py", line 76, in edit_profile
    return redirect(url_for('edit_profile'))
  File "<string>", line 2, in commit
  File "c:\users\admin\pycharmprojects\fdemo\venv\lib\site-packages\sqlalchemy\orm\session.py", line 1428, in commit
    self._transaction.commit(_to_root=self.future)
  File "c:\users\admin\pycharmprojects\fdemo\venv\lib\site-packages\sqlalchemy\orm\session.py", line 829, in commit
    self._prepare_impl()
  File "c:\users\admin\pycharmprojects\fdemo\venv\lib\site-packages\sqlalchemy\orm\session.py", line 808, in _prepare_impl
    self.session.flush()
  File "c:\users\admin\pycharmprojects\fdemo\venv\lib\site-packages\sqlalchemy\orm\session.py", line 3298, in flush
    self._flush(objects)
  File "c:\users\admin\pycharmprojects\fdemo\venv\lib\site-packages\sqlalchemy\orm\session.py", line 3438, in _flush
    transaction.rollback(_capture_exception=True)
  File "c:\users\admin\pycharmprojects\fdemo\venv\lib\site-packages\sqlalchemy\util\langhelpers.py", line 70, in __exit__
    compat.raise_(
  File "c:\users\admin\pycharmprojects\fdemo\venv\lib\site-packages\sqlalchemy\util\compat.py", line 207, in raise_
    raise exception
  File "c:\users\admin\pycharmprojects\fdemo\venv\lib\site-packages\sqlalchemy\orm\session.py", line 3398, in _flush
    flush_context.execute()
  File "c:\users\admin\pycharmprojects\fdemo\venv\lib\site-packages\sqlalchemy\orm\unitofwork.py", line 456, in execute
    rec.execute(self)
  File "c:\users\admin\pycharmprojects\fdemo\venv\lib\site-packages\sqlalchemy\orm\unitofwork.py", line 630, in execute
    util.preloaded.orm_persistence.save_obj(
  File "c:\users\admin\pycharmprojects\fdemo\venv\lib\site-packages\sqlalchemy\orm\persistence.py", line 234, in save_obj
    _emit_update_statements(
  File "c:\users\admin\pycharmprojects\fdemo\venv\lib\site-packages\sqlalchemy\orm\persistence.py", line 998, in _emit_update_statements
    c = connection._execute_20(
  File "c:\users\admin\pycharmprojects\fdemo\venv\lib\site-packages\sqlalchemy\engine\base.py", line 1583, in _execute_20
    return meth(self, args_10style, kwargs_10style, execution_options)
  File "c:\users\admin\pycharmprojects\fdemo\venv\lib\site-packages\sqlalchemy\sql\elements.py", line 323, in _execute_on_connection
    return connection._execute_clauseelement(
  File "c:\users\admin\pycharmprojects\fdemo\venv\lib\site-packages\sqlalchemy\engine\base.py", line 1452, in _execute_clauseelement
    ret = self._execute_context(
  File "c:\users\admin\pycharmprojects\fdemo\venv\lib\site-packages\sqlalchemy\engine\base.py", line 1814, in _execute_context
    self._handle_dbapi_exception(
  File "c:\users\admin\pycharmprojects\fdemo\venv\lib\site-packages\sqlalchemy\engine\base.py", line 1995, in _handle_dbapi_exception
    util.raise_(
  File "c:\users\admin\pycharmprojects\fdemo\venv\lib\site-packages\sqlalchemy\util\compat.py", line 207, in raise_
    raise exception
  File "c:\users\admin\pycharmprojects\fdemo\venv\lib\site-packages\sqlalchemy\engine\base.py", line 1771, in _execute_context
    self.dialect.do_execute(
  File "c:\users\admin\pycharmprojects\fdemo\venv\lib\site-packages\sqlalchemy\engine\default.py", line 717, in do_execute
    cursor.execute(statement, parameters)
sqlalchemy.exc.IntegrityError: (sqlite3.IntegrityError) UNIQUE constraint failed: user.username
[SQL: UPDATE user SET username=?, about_me=? WHERE user.id = ?]
[parameters: ('nhat', 'my name is Phat', 1)]
(Background on this error at: https://sqlalche.me/e/14/gkpj)
2021-09-24 20:10:13,475 INFO: Myblog startup [in C:\Users\Admin\PycharmProjects\fDemo\app\__init__.py:44]
2021-09-24 20:10:20,814 INFO: Myblog startup [in C:\Users\Admin\PycharmProjects\fDemo\app\__init__.py:44]
2021-09-24 20:10:23,153 INFO: Myblog startup [in C:\Users\Admin\PycharmProjects\fDemo\app\__init__.py:44]
2021-09-24 20:11:02,597 INFO: Myblog startup [in C:\Users\Admin\PycharmProjects\fDemo\app\__init__.py:44]
2021-09-24 20:16:46,002 INFO: Myblog startup [in C:\Users\Admin\PycharmProjects\fDemo\app\__init__.py:44]
2021-09-24 20:17:40,504 INFO: Myblog startup [in C:\Users\Admin\PycharmProjects\fDemo\app\__init__.py:44]
2021-09-24 20:18:37,087 INFO: Myblog startup [in C:\Users\Admin\PycharmProjects\fDemo\app\__init__.py:44]
2021-11-11 11:53:16,633 INFO: Myblog startup [in C:\Users\Admin\PycharmProjects\fDemo\app\__init__.py:52]
2021-11-11 12:19:08,902 INFO: Myblog startup [in C:\Users\Admin\PycharmProjects\fDemo\app\__init__.py:52]
2021-11-11 12:20:57,002 INFO: Myblog startup [in C:\Users\Admin\PycharmProjects\fDemo\app\__init__.py:52]
